Workbook

Sheet README
B1: Rippling New-Business Staffing Model (simplified)
B2: Built on the fictional case dataset: 12 months (Feb-2021 to Jan-2022) x 5 employee-size buckets.
B4: Purpose | C4: Analyze the new-business funnel by segment and size the SDR, AE and SC capacity each segment needs.
B5: Colors | C5: Blue = editable input. Black = formula. Green = link from another tab. Yellow fill = key assumption.
B6: Tabs | C6: Inputs -> Data -> Funnel -> Staffing -> Cost_Optional -> Checks.
B7: Inputs | C7: Time windows, bucket-to-segment map, the 5 staffing assumptions, and the upside switch. ALL staffing assumptions are ILLUSTRATIVE, not Rippling data.
B8: Data | C8: The 60 source rows from the CSV (blue) plus three formula columns: segment, early-period flag, baseline-period flag.
B9: Funnel | C9: Funnel by segment and bucket, monthly trend, and early (Feb-Jul-21) vs baseline (Aug-Oct-21) comparison behind the three findings.
B10: Staffing | C10: Baseline demand -> required FTE -> recommended headcount (ROUNDUP), ratios and expected ARR. Plus the upside case (lead-to-demo recovers).
B11: Cost_Optional | C11: Appendix only: a simple illustrative cost of the recommended headcount. It is not an ROI or payback analysis.
B12: Checks | C12: Confirms the model reconciles to the source data. Every row should read TRUE.
B13: Staffing formulas | C13: SDR FTE = leads / (SDR lead capacity x utilization). AE FTE = demos / (AE demo capacity x utilization). SC FTE = demos x SC engagement rate / (SC capacity x utilization).
B14: Rounding | C14: Dedicated roles: ROUNDUP per segment. Shared SC pool (Velocity + Emerging MM + Core MM): ROUNDUP of the combined FTE. Recommended headcount therefore always covers modeled workload.
B15: Caveat 1 | C15: Headcount shown is REQUIRED CAPACITY. Current headcount is not in the dataset, so this is not a hiring number. Enter current headcount on the Staffing tab to see a gap.
... B18: Caveat 4 | C18: ARR per lead is revenue yield, not ROI. The dataset has no cost data.

Sheet Inputs
A1: Inputs (edit blue cells only)
A2: All staffing assumptions are ILLUSTRATIVE planning assumptions, not company data.
A4: 1. Time windows
B5: Early period start | C5: 44228 | G5: Early period = Feb-Jul 2021 (first 6 months of data).
B6: Early period end | C6: 44378
B7: Baseline period start | C7: 44409 | G7: Baseline = Aug-Oct 2021, the latest 3 months before the Nov-Dec dip.
B8: Baseline period end | C8: 44470 | G8: Nov-Dec excluded: seen once only, so it is not confirmed seasonality. Jan-22 rebounded to a record.
A10: 2. Segment map (dataset bucket -> segment)
B11: Employee bucket | C11: Segment | D11: Sales motion
B12: 1-10 | C12: Velocity (1-50) | D12: Velocity | G12: Boundaries sit where the data changes: ARR/logo jumps ~2.3x at 50, conversion halves at 100 and again at 500.
B13: 11-50 | C13: Velocity (1-50) | D13: Velocity
B14: 51-100 | C14: Emerging MM (51-100) | D14: Mid-Market
B15: 101-500 | C15: Core MM (101-500) | D15: Mid-Market
B16: 501+ | C16: Enterprise (501+) | D16: Enterprise
A18: 3. Staffing assumptions (ILLUSTRATIVE; per ramped employee per month)
B19: Assumption | C19: Velocity (1-50) | D19: Emerging MM (51-100) | E19: Core MM (101-500) | F19: Enterprise (501+) | G19: Why this value (illustrative)
B20: SDR lead capacity (high-intent leads worked / month) | C20: 300 | D20: 200 | E20: 175 | F20: 125 | G20: Larger accounts need more research and follow-up per lead. 200/month = ~10 new leads per working day.
B21: AE demo capacity (demos held / month) | C21: 45 | D21: 30 | E21: 20 | F21: 12 | G21: Includes follow-up on the opps each demo creates. Velocity ~2 demos/day; Enterprise demos are multi-session.
B22: SC engagement rate (% of demos needing an SC) | C22: 0.05 | D22: 0.15 | E22: 0.5 | F22: 1 | G22: Rises with complexity seen in the data: demo->opp falls from ~80% to ~65% and demos per logo rise from 3.7 to 7.8.
B23: SC engagement capacity (SC-supported demos / month) | C23: 30 | D23: 30 | E23: 30 | F23: 20 | G23: Enterprise engagements are deeper (discovery, custom demo, security review).
B24: Target utilization | C24: 0.85 | D24: 0.85 | E24: 0.85 | F24: 0.85 | G24: 15% buffer for PTO, training, admin and demand spikes.
A26: 4. Upside sensitivity
B27: Lead-to-demo recovers to early-period level? (1 = yes) | C27: 1 | D27: 1 | E27: 1 | F27: 0 | G27: Enterprise = 0: its lead-to-demo did not decline. The upside is a 'what if', not a forecast.
A29: 5. Shared resource pool
B30: One shared SC pool covers Velocity, Emerging MM and Core MM. Below 100 employees each segment needs less than one SC, so the pool is sized on
B31: the combined FTE (ROUNDUP). Enterprise SCs are dedicated. All SDR and AE roles are dedicated per segment.
B32: In practice, Velocity and Emerging MM SDRs could share one inbound queue, with 51-100 leads routed first.

Sheet Data
A1: Month | B1: Employee bucket | C1: Leads | D1: Demos | E1: Qualified opps | F1: Logos | G1: ARR ($) | H1: Segment | I1: Early (1/0) | J1: Baseline (1/0)
A2: 44228 | B2: 1-10 | C2: 127 | D2: 55 | E2: 43 | F2: 14 | G2: 43406 | H2: =INDEX(Inputs!$C$12:$C$16,MATCH(B2,Inputs!$B$12:$B$16,0)) -> Velocity (1-50) | I2: =IF(AND(A2>=Inputs!$C$5,A2<=Inputs!$C$6),1,0) -> 1 | J2: =IF(AND(A2>=Inputs!$C$7,A2<=Inputs!$C$8),1,0) -> 0
A3: 44228 | B3: 11-50 | C3: 208 | D3: 92 | E3: 72 | F3: 23 | G3: 90266 | H3: =INDEX(Inputs!$C$12:$C$16,MATCH(B3,Inputs!$B$12:$B$16,0)) -> Velocity (1-50) | I3: =IF(AND(A3>=Inputs!$C$5,A3<=Inputs!$C$6),1,0) -> 1 | J3: =IF(AND(A3>=Inputs!$C$7,A3<=Inputs!$C$8),1,0) -> 0
A4: 44228 | B4: 51-100 | C4: 231 | D4: 97 | E4: 77 | F4: 25 | G4: 228974 | H4: =INDEX(Inputs!$C$12:$C$16,MATCH(B4,Inputs!$B$12:$B$16,0)) -> Emerging MM (51-100) | I4: =IF(AND(A4>=Inputs!$C$5,A4<=Inputs!$C$6),1,0) -> 1 | J4: =IF(AND(A4>=Inputs!$C$7,A4<=Inputs!$C$8),1,0) -> 0
A5: 44228 | B5: 101-500 | C5: 462 | D5: 143 | E5: 99 | F5: 25 | G5: 273899 | H5: =INDEX(Inputs!$C$12:$C$16,MATCH(B5,Inputs!$B$12:$B$16,0)) -> Core MM (101-500) | I5: =IF(AND(A5>=Inputs!$C$5,A5<=Inputs!$C$6),1,0) -> 1 | J5: =IF(AND(A5>=Inputs!$C$7,A5<=Inputs!$C$8),1,0) -> 0
A6: 44228 | B6: 501+ | C6: 127 | D6: 23 | E6: 15 | F6: 3 | G6: 53825 | H6: =INDEX(Inputs!$C$12:$C$16,MATCH(B6,Inputs!$B$12:$B$16,0)) -> Enterprise (501+) | I6: =IF(AND(A6>=Inputs!$C$5,A6<=Inputs!$C$6),1,0) -> 1 | J6: =IF(AND(A6>=Inputs!$C$7,A6<=Inputs!$C$8),1,0) -> 0
A7: 44256 | B7: 1-10 | C7: 109 | D7: 46 | E7: 36 | F7: 12 | G7: 35764 | H7: =INDEX(Inputs!$C$12:$C$16,MATCH(B7,Inputs!$B$12:$B$16,0)) -> Velocity (1-50) | I7: =IF(AND(A7>=Inputs!$C$5,A7<=Inputs!$C$6),1,0) -> 1 | J7: =IF(AND(A7>=Inputs!$C$7,A7<=Inputs!$C$8),1,0) -> 0
A8: 44256 | B8: 11-50 | C8: 170 | D8: 73 | E8: 59 | F8: 19 | G8: 77239 | H8: =INDEX(Inputs!$C$12:$C$16,MATCH(B8,Inputs!$B$12:$B$16,0)) -> Velocity (1-50) | I8: =IF(AND(A8>=Inputs!$C$5,A8<=Inputs!$C$6),1,0) -> 1 | J8: =IF(AND(A8>=Inputs!$C$7,A8<=Inputs!$C$8),1,0) -> 0
A9: 44256 | B9: 51-100 | C9: 231 | D9: 92 | E9: 73 | F9: 24 | G9: 219137 | H9: =INDEX(Inputs!$C$12:$C$16,MATCH(B9,Inputs!$B$12:$B$16,0)) -> Emerging MM (51-100) | I9: =IF(AND(A9>=Inputs!$C$5,A9<=Inputs!$C$6),1,0) -> 1 | J9: =IF(AND(A9>=Inputs!$C$7,A9<=Inputs!$C$8),1,0) -> 0
A10: 44256 | B10: 101-500 | C10: 510 | D10: 153 | E10: 104 | F10: 26 | G10: 274151 | H10: =INDEX(Inputs!$C$12:$C$16,MATCH(B10,Inputs!$B$12:$B$16,0)) -> Core MM (101-500) | I10: =IF(AND(A10>=Inputs!$C$5,A10<=Inputs!$C$6),1,0) -> 1 | J10: =IF(AND(A10>=Inputs!$C$7,A10<=Inputs!$C$8),1,0) -> 0
A11: 44256 | B11: 501+ | C11: 194 | D11: 37 | E11: 24 | F11: 5 | G11: 111848 | H11: =INDEX(Inputs!$C$12:$C$16,MATCH(B11,Inputs!$B$12:$B$16,0)) -> Enterprise (501+) | I11: =IF(AND(A11>=Inputs!$C$5,A11<=Inputs!$C$6),1,0) -> 1 | J11: =IF(AND(A11>=Inputs!$C$7,A11<=Inputs!$C$8),1,0) -> 0
A12: 44287 | B12: 1-10 | C12: 132 | D12: 53 | E12: 43 | F12: 14 | G12: 39525 | H12: =INDEX(Inputs!$C$12:$C$16,MATCH(B12,Inputs!$B$12:$B$16,0)) -> Velocity (1-50) | I12: =IF(AND(A12>=Inputs!$C$5,A12<=Inputs!$C$6),1,0) -> 1 | J12: =IF(AND(A12>=Inputs!$C$7,A12<=Inputs!$C$8),1,0) -> 0
A13: 44287 | B13: 11-50 | C13: 197 | D13: 79 | E13: 62 | F13: 21 | G13: 83326 | H13: =INDEX(Inputs!$C$12:$C$16,MATCH(B13,Inputs!$B$12:$B$16,0)) -> Velocity (1-50) | I13: =IF(AND(A13>=Inputs!$C$5,A13<=Inputs!$C$6),1,0) -> 1 | J13: =IF(AND(A13>=Inputs!$C$7,A13<=Inputs!$C$8),1,0) -> 0
... A61: 44562 | B61: 501+ | C61: 402 | D61: 84 | E61: 54 | F61: 11 | G61: 284756 | H61: =INDEX(Inputs!$C$12:$C$16,MATCH(B61,Inputs!$B$12:$B$16,0)) -> Enterprise (501+) | I61: =IF(AND(A61>=Inputs!$C$5,A61<=Inputs!$C$6),1,0) -> 0 | J61: =IF(AND(A61>=Inputs!$C$7,A61<=Inputs!$C$8),1,0) -> 0

Sheet Funnel
A1: Funnel analysis (all values are formulas on the Data tab)
A2: Rates = summed numerator / summed denominator. Same-month ratios, not cohort conversion.
A4: A. 12-month funnel by segment (Feb-21 to Jan-22)
A5: Segment | B5: Leads | C5: Demos | D5: Qual opps | E5: Logos | F5: ARR | G5: Lead->Demo | H5: Demo->Opp | I5: Opp->Win | J5: Lead->Win | K5: ARR / logo | L5: ARR / lead | M5: Lead share | N5: ARR share | O5: Demos / logo
A6: Velocity (1-50) | B6: =SUMIFS(Data!$C$2:$C$61,Data!$H$2:$H$61,$A6) -> 3709 | C6: =SUMIFS(Data!$D$2:$D$61,Data!$H$2:$H$61,$A6) -> 1373 | D6: =SUMIFS(Data!$E$2:$E$61,Data!$H$2:$H$61,$A6) -> 1096 | E6: =SUMIFS(Data!$F$2:$F$61,Data!$H$2:$H$61,$A6) -> 371 | F6: =SUMIFS(Data!$G$2:$G$61,Data!$H$2:$H$61,$A6) -> 1368049 | G6: =C6/B6 -> 0.37018064 | H6: =D6/C6 -> 0.798252 | I6: =E6/D6 -> 0.33850365 | J6: =E6/B6 -> 0.10002696 | K6: =F6/E6 -> 3687.4636 | L6: =F6/B6 -> 368.84578 | M6: =B6/B$10 -> 0.216243 | N6: =F6/F$10 -> 0.1361735 | O6: =C6/E6 -> 3.7008086
A7: Emerging MM (51-100) | B7: =SUMIFS(Data!$C$2:$C$61,Data!$H$2:$H$61,$A7) -> 3246 | C7: =SUMIFS(Data!$D$2:$D$61,Data!$H$2:$H$61,$A7) -> 1163 | D7: =SUMIFS(Data!$E$2:$E$61,Data!$H$2:$H$61,$A7) -> 926 | E7: =SUMIFS(Data!$F$2:$F$61,Data!$H$2:$H$61,$A7) -> 312 | F7: =SUMIFS(Data!$G$2:$G$61,Data!$H$2:$H$61,$A7) -> 2905721 | G7: =C7/B7 -> 0.35828712 | H7: =D7/C7 -> 0.79621668 | I7: =E7/D7 -> 0.33693305 | J7: =E7/B7 -> 0.096118299 | K7: =F7/E7 -> 9313.2083 | L7: =F7/B7 -> 895.16975 | M7: =B7/B$10 -> 0.18924907 | N7: =F7/F$10 -> 0.28923102 | O7: =C7/E7 -> 3.7275641
A8: Core MM (101-500) | B8: =SUMIFS(Data!$C$2:$C$61,Data!$H$2:$H$61,$A8) -> 6962 | C8: =SUMIFS(Data!$D$2:$D$61,Data!$H$2:$H$61,$A8) -> 1807 | D8: =SUMIFS(Data!$E$2:$E$61,Data!$H$2:$H$61,$A8) -> 1264 | E8: =SUMIFS(Data!$F$2:$F$61,Data!$H$2:$H$61,$A8) -> 321 | F8: =SUMIFS(Data!$G$2:$G$61,Data!$H$2:$H$61,$A8) -> 4000078 | G8: =C8/B8 -> 0.25955185 | H8: =D8/C8 -> 0.69950194 | I8: =E8/D8 -> 0.2539557 | J8: =E8/B8 -> 0.04610744 | K8: =F8/E8 -> 12461.302 | L8: =F8/B8 -> 574.55875 | M8: =B8/B$10 -> 0.40590019 | N8: =F8/F$10 -> 0.39816164 | O8: =C8/E8 -> 5.6292835
A9: Enterprise (501+) | B9: =SUMIFS(Data!$C$2:$C$61,Data!$H$2:$H$61,$A9) -> 3235 | C9: =SUMIFS(Data!$D$2:$D$61,Data!$H$2:$H$61,$A9) -> 608 | D9: =SUMIFS(Data!$E$2:$E$61,Data!$H$2:$H$61,$A9) -> 396 | E9: =SUMIFS(Data!$F$2:$F$61,Data!$H$2:$H$61,$A9) -> 78 | F9: =SUMIFS(Data!$G$2:$G$61,Data!$H$2:$H$61,$A9) -> 1772519 | G9: =C9/B9 -> 0.18794436 | H9: =D9/C9 -> 0.65131579 | I9: =E9/D9 -> 0.1969697 | J9: =E9/B9 -> 0.024111283 | K9: =F9/E9 -> 22724.603 | L9: =F9/B9 -> 547.91932 | M9: =B9/B$10 -> 0.18860774 | N9: =F9/F$10 -> 0.17643383 | O9: =C9/E9 -> 7.7948718
A10: Total | B10: =SUM(B6:B9) -> 17152 | C10: =SUM(C6:C9) -> 4951 | D10: =SUM(D6:D9) -> 3682 | E10: =SUM(E6:E9) -> 1082 | F10: =SUM(F6:F9) -> 10046367 | G10: =C10/B10 -> 0.28865438 | H10: =D10/C10 -> 0.74368814 | I10: =E10/D10 -> 0.29386203 | J10: =E10/B10 -> 0.063083022 | K10: =F10/E10 -> 9284.9972 | L10: =F10/B10 -> 585.72569 | M10: =B10/B$10 -> 1 | N10: =F10/F$10 -> 1 | O10: =C10/E10 -> 4.5757856
A12: B. 12-month funnel by employee bucket (detail)
A13: Bucket | B13: Leads | C13: Demos | D13: Qual opps | E13: Logos | F13: ARR | G13: Lead->Demo | H13: Demo->Opp | I13: Opp->Win | J13: Lead->Win | K13: ARR / logo | L13: ARR / lead | M13: Lead share | N13: ARR share | O13: Demos / logo
A14: 1-10 | B14: =SUMIFS(Data!$C$2:$C$61,Data!$B$2:$B$61,$A14) -> 1180 | C14: =SUMIFS(Data!$D$2:$D$61,Data!$B$2:$B$61,$A14) -> 437 | D14: =SUMIFS(Data!$E$2:$E$61,Data!$B$2:$B$61,$A14) -> 351 | E14: =SUMIFS(Data!$F$2:$F$61,Data!$B$2:$B$61,$A14) -> 118 | F14: =SUMIFS(Data!$G$2:$G$61,Data!$B$2:$B$61,$A14) -> 352503 | G14: =C14/B14 -> 0.37033898 | H14: =D14/C14 -> 0.80320366 | I14: =E14/D14 -> 0.33618234 | J14: =E14/B14 -> 0.1 | K14: =F14/E14 -> 2987.3136 | L14: =F14/B14 -> 298.73136 | M14: =B14/B$19 -> 0.068796642 | N14: =F14/F$19 -> 0.035087609 | O14: =C14/E14 -> 3.7033898
A15: 11-50 | B15: =SUMIFS(Data!$C$2:$C$61,Data!$B$2:$B$61,$A15) -> 2529 | C15: =SUMIFS(Data!$D$2:$D$61,Data!$B$2:$B$61,$A15) -> 936 | D15: =SUMIFS(Data!$E$2:$E$61,Data!$B$2:$B$61,$A15) -> 745 | E15: =SUMIFS(Data!$F$2:$F$61,Data!$B$2:$B$61,$A15) -> 253 | F15: =SUMIFS(Data!$G$2:$G$61,Data!$B$2:$B$61,$A15) -> 1015546 | G15: =C15/B15 -> 0.37010676 | H15: =D15/C15 -> 0.79594017 | I15: =E15/D15 -> 0.33959732 | J15: =E15/B15 -> 0.10003954 | K15: =F15/E15 -> 4014.0158 | L15: =F15/B15 -> 401.5603 | M15: =B15/B$19 -> 0.14744636 | N15: =F15/F$19 -> 0.1010859 | O15: =C15/E15 -> 3.6996047
A16: 51-100 | B16: =SUMIFS(Data!$C$2:$C$61,Data!$B$2:$B$61,$A16) -> 3246 | C16: =SUMIFS(Data!$D$2:$D$61,Data!$B$2:$B$61,$A16) -> 1163 | D16: =SUMIFS(Data!$E$2:$E$61,Data!$B$2:$B$61,$A16) -> 926 | E16: =SUMIFS(Data!$F$2:$F$61,Data!$B$2:$B$61,$A16) -> 312 | F16: =SUMIFS(Data!$G$2:$G$61,Data!$B$2:$B$61,$A16) -> 2905721 | G16: =C16/B16 -> 0.35828712 | H16: =D16/C16 -> 0.79621668 | I16: =E16/D16 -> 0.33693305 | J16: =E16/B16 -> 0.096118299 | K16: =F16/E16 -> 9313.2083 | L16: =F16/B16 -> 895.16975 | M16: =B16/B$19 -> 0.18924907 | N16: =F16/F$19 -> 0.28923102 | O16: =C16/E16 -> 3.7275641
A17: 101-500 | B17: =SUMIFS(Data!$C$2:$C$61,Data!$B$2:$B$61,$A17) -> 6962 | C17: =SUMIFS(Data!$D$2:$D$61,Data!$B$2:$B$61,$A17) -> 1807 | D17: =SUMIFS(Data!$E$2:$E$61,Data!$B$2:$B$61,$A17) -> 1264 | E17: =SUMIFS(Data!$F$2:$F$61,Data!$B$2:$B$61,$A17) -> 321 | F17: =SUMIFS(Data!$G$2:$G$61,Data!$B$2:$B$61,$A17) -> 4000078 | G17: =C17/B17 -> 0.25955185 | H17: =D17/C17 -> 0.69950194 | I17: =E17/D17 -> 0.2539557 | J17: =E17/B17 -> 0.04610744 | K17: =F17/E17 -> 12461.302 | L17: =F17/B17 -> 574.55875 | M17: =B17/B$19 -> 0.40590019 | N17: =F17/F$19 -> 0.39816164 | O17: =C17/E17 -> 5.6292835
A18: 501+ | B18: =SUMIFS(Data!$C$2:$C$61,Data!$B$2:$B$61,$A18) -> 3235 | C18: =SUMIFS(Data!$D$2:$D$61,Data!$B$2:$B$61,$A18) -> 608 | D18: =SUMIFS(Data!$E$2:$E$61,Data!$B$2:$B$61,$A18) -> 396 | E18: =SUMIFS(Data!$F$2:$F$61,Data!$B$2:$B$61,$A18) -> 78 | F18: =SUMIFS(Data!$G$2:$G$61,Data!$B$2:$B$61,$A18) -> 1772519 | G18: =C18/B18 -> 0.18794436 | H18: =D18/C18 -> 0.65131579 | I18: =E18/D18 -> 0.1969697 | J18: =E18/B18 -> 0.024111283 | K18: =F18/E18 -> 22724.603 | L18: =F18/B18 -> 547.91932 | M18: =B18/B$19 -> 0.18860774 | N18: =F18/F$19 -> 0.17643383 | O18: =C18/E18 -> 7.7948718
A19: Total | B19: =SUM(B14:B18) -> 17152 | C19: =SUM(C14:C18) -> 4951 | D19: =SUM(D14:D18) -> 3682 | E19: =SUM(E14:E18) -> 1082 | F19: =SUM(F14:F18) -> 10046367 | G19: =C19/B19 -> 0.28865438 | H19: =D19/C19 -> 0.74368814 | I19: =E19/D19 -> 0.29386203 | J19: =E19/B19 -> 0.063083022 | K19: =F19/E19 -> 9284.9972 | L19: =F19/B19 -> 585.72569 | M19: =B19/B$19 -> 1 | N19: =F19/F$19 -> 1 | O19: =C19/E19 -> 4.5757856
A21: C. Monthly trend (all segments)
A22: Month | B22: Leads | C22: Demos | D22: Logos | E22: ARR | F22: Lead->Demo | G22: Demo->Win | H22: ARR / logo | I22: Leads from 101+ (share)
A23: 44228 | B23: =SUMIFS(Data!$C$2:$C$61,Data!$A$2:$A$61,$A23) -> 1155 | C23: =SUMIFS(Data!$D$2:$D$61,Data!$A$2:$A$61,$A23) -> 410 | D23: =SUMIFS(Data!$F$2:$F$61,Data!$A$2:$A$61,$A23) -> 90 | E23: =SUMIFS(Data!$G$2:$G$61,Data!$A$2:$A$61,$A23) -> 690370 | F23: =C23/B23 -> 0.35497835 | G23: =D23/C23 -> 0.2195122 | H23: =E23/D23 -> 7670.7778 | I23: =(SUMIFS(Data!$C$2:$C$61,Data!$A$2:$A$61,$A23,Data!$B$2:$B$61,"101-500")+SUMIFS(Data!$C$2:$C$61,Data!$A$2:$A$61,$A23,Data!$B$2:$B$61,"501+"))/B23 -> 0.50995671
A24: 44256 | B24: =SUMIFS(Data!$C$2:$C$61,Data!$A$2:$A$61,$A24) -> 1214 | C24: =SUMIFS(Data!$D$2:$D$61,Data!$A$2:$A$61,$A24) -> 401 | D24: =SUMIFS(Data!$F$2:$F$61,Data!$A$2:$A$61,$A24) -> 86 | E24: =SUMIFS(Data!$G$2:$G$61,Data!$A$2:$A$61,$A24) -> 718139 | F24: =C24/B24 -> 0.33031301 | G24: =D24/C24 -> 0.21446384 | H24: =E24/D24 -> 8350.4535 | I24: =(SUMIFS(Data!$C$2:$C$61,Data!$A$2:$A$61,$A24,Data!$B$2:$B$61,"101-500")+SUMIFS(Data!$C$2:$C$61,Data!$A$2:$A$61,$A24,Data!$B$2:$B$61,"501+"))/B24 -> 0.57990115
A25: 44287 | B25: =SUMIFS(Data!$C$2:$C$61,Data!$A$2:$A$61,$A25) -> 1315 | C25: =SUMIFS(Data!$D$2:$D$61,Data!$A$2:$A$61,$A25) -> 416 | D25: =SUMIFS(Data!$F$2:$F$61,Data!$A$2:$A$61,$A25) -> 93 | E25: =SUMIFS(Data!$G$2:$G$61,Data!$A$2:$A$61,$A25) -> 756173 | F25: =C25/B25 -> 0.31634981 | G25: =D25/C25 -> 0.22355769 | H25: =E25/D25 -> 8130.8925 | I25: =(SUMIFS(Data!$C$2:$C$61,Data!$A$2:$A$61,$A25,Data!$B$2:$B$61,"101-500")+SUMIFS(Data!$C$2:$C$61,Data!$A$2:$A$61,$A25,Data!$B$2:$B$61,"501+"))/B25 -> 0.56958175
A26: 44317 | B26: =SUMIFS(Data!$C$2:$C$61,Data!$A$2:$A$61,$A26) -> 1399 | C26: =SUMIFS(Data!$D$2:$D$61,Data!$A$2:$A$61,$A26) -> 424 | D26: =SUMIFS(Data!$F$2:$F$61,Data!$A$2:$A$61,$A26) -> 103 | E26: =SUMIFS(Data!$G$2:$G$61,Data!$A$2:$A$61,$A26) -> 925457 | F26: =C26/B26 -> 0.30307362 | G26: =D26/C26 -> 0.24292453 | H26: =E26/D26 -> 8985.0194 | I26: =(SUMIFS(Data!$C$2:$C$61,Data!$A$2:$A$61,$A26,Data!$B$2:$B$61,"101-500")+SUMIFS(Data!$C$2:$C$61,Data!$A$2:$A$61,$A26,Data!$B$2:$B$61,"501+"))/B26 -> 0.59971408
A27: 44348 | B27: =SUMIFS(Data!$C$2:$C$61,Data!$A$2:$A$61,$A27) -> 1444 | C27: =SUMIFS(Data!$D$2:$D$61,Data!$A$2:$A$61,$A27) -> 423 | D27: =SUMIFS(Data!$F$2:$F$61,Data!$A$2:$A$61,$A27) -> 94 | E27: =SUMIFS(Data!$G$2:$G$61,Data!$A$2:$A$61,$A27) -> 856811 | F27: =C27/B27 -> 0.29293629 | G27: =D27/C27 -> 0.22222222 | H27: =E27/D27 -> 9115.0106 | I27: =(SUMIFS(Data!$C$2:$C$61,Data!$A$2:$A$61,$A27,Data!$B$2:$B$61,"101-500")+SUMIFS(Data!$C$2:$C$61,Data!$A$2:$A$61,$A27,Data!$B$2:$B$61,"501+"))/B27 -> 0.57963989
A28: 44378 | B28: =SUMIFS(Data!$C$2:$C$61,Data!$A$2:$A$61,$A28) -> 1560 | C28: =SUMIFS(Data!$D$2:$D$61,Data!$A$2:$A$61,$A28) -> 450 | D28: =SUMIFS(Data!$F$2:$F$61,Data!$A$2:$A$61,$A28) -> 107 | E28: =SUMIFS(Data!$G$2:$G$61,Data!$A$2:$A$61,$A28) -> 931670 | F28: =C28/B28 -> 0.28846154 | G28: =D28/C28 -> 0.23777778 | H28: =E28/D28 -> 8707.1963 | I28: =(SUMIFS(Data!$C$2:$C$61,Data!$A$2:$A$61,$A28,Data!$B$2:$B$61,"101-500")+SUMIFS(Data!$C$2:$C$61,Data!$A$2:$A$61,$A28,Data!$B$2:$B$61,"501+"))/B28 -> 0.56987179
A29: 44409 | B29: =SUMIFS(Data!$C$2:$C$61,Data!$A$2:$A$61,$A29) -> 1605 | C29: =SUMIFS(Data!$D$2:$D$61,Data!$A$2:$A$61,$A29) -> 454 | D29: =SUMIFS(Data!$F$2:$F$61,Data!$A$2:$A$61,$A29) -> 100 | E29: =SUMIFS(Data!$G$2:$G$61,Data!$A$2:$A$61,$A29) -> 943441 | F29: =C29/B29 -> 0.28286604 | G29: =D29/C29 -> 0.22026432 | H29: =E29/D29 -> 9434.41 | I29: =(SUMIFS(Data!$C$2:$C$61,Data!$A$2:$A$61,$A29,Data!$B$2:$B$61,"101-500")+SUMIFS(Data!$C$2:$C$61,Data!$A$2:$A$61,$A29,Data!$B$2:$B$61,"501+"))/B29 -> 0.59003115
A30: 44440 | B30: =SUMIFS(Data!$C$2:$C$61,Data!$A$2:$A$61,$A30) -> 1652 | C30: =SUMIFS(Data!$D$2:$D$61,Data!$A$2:$A$61,$A30) -> 466 | D30: =SUMIFS(Data!$F$2:$F$61,Data!$A$2:$A$61,$A30) -> 97 | E30: =SUMIFS(Data!$G$2:$G$61,Data!$A$2:$A$61,$A30) -> 954831 | F30: =C30/B30 -> 0.28208232 | G30: =D30/C30 -> 0.20815451 | H30: =E30/D30 -> 9843.6186 | I30: =(SUMIFS(Data!$C$2:$C$61,Data!$A$2:$A$61,$A30,Data!$B$2:$B$61,"101-500")+SUMIFS(Data!$C$2:$C$61,Data!$A$2:$A$61,$A30,Data!$B$2:$B$61,"501+"))/B30 -> 0.61985472
A31: 44470 | B31: =SUMIFS(Data!$C$2:$C$61,Data!$A$2:$A$61,$A31) -> 1877 | C31: =SUMIFS(Data!$D$2:$D$61,Data!$A$2:$A$61,$A31) -> 528 | D31: =SUMIFS(Data!$F$2:$F$61,Data!$A$2:$A$61,$A31) -> 117 | E31: =SUMIFS(Data!$G$2:$G$61,Data!$A$2:$A$61,$A31) -> 1180005 | F31: =C31/B31 -> 0.28129995 | G31: =D31/C31 -> 0.22159091 | H31: =E31/D31 -> 10085.513 | I31: =(SUMIFS(Data!$C$2:$C$61,Data!$A$2:$A$61,$A31,Data!$B$2:$B$61,"101-500")+SUMIFS(Data!$C$2:$C$61,Data!$A$2:$A$61,$A31,Data!$B$2:$B$61,"501+"))/B31 -> 0.62972829
A32: 44501 | B32: =SUMIFS(Data!$C$2:$C$61,Data!$A$2:$A$61,$A32) -> 1001 | C32: =SUMIFS(Data!$D$2:$D$61,Data!$A$2:$A$61,$A32) -> 229 | D32: =SUMIFS(Data!$F$2:$F$61,Data!$A$2:$A$61,$A32) -> 41 | E32: =SUMIFS(Data!$G$2:$G$61,Data!$A$2:$A$61,$A32) -> 429791 | F32: =C32/B32 -> 0.22877123 | G32: =D32/C32 -> 0.1790393 | H32: =E32/D32 -> 10482.707 | I32: =(SUMIFS(Data!$C$2:$C$61,Data!$A$2:$A$61,$A32,Data!$B$2:$B$61,"101-500")+SUMIFS(Data!$C$2:$C$61,Data!$A$2:$A$61,$A32,Data!$B$2:$B$61,"501+"))/B32 -> 0.63036963
A33: 44531 | B33: =SUMIFS(Data!$C$2:$C$61,Data!$A$2:$A$61,$A33) -> 1015 | C33: =SUMIFS(Data!$D$2:$D$61,Data!$A$2:$A$61,$A33) -> 212 | D33: =SUMIFS(Data!$F$2:$F$61,Data!$A$2:$A$61,$A33) -> 34 | E33: =SUMIFS(Data!$G$2:$G$61,Data!$A$2:$A$61,$A33) -> 375643 | F33: =C33/B33 -> 0.208867 | G33: =D33/C33 -> 0.16037736 | H33: =E33/D33 -> 11048.324 | I33: =(SUMIFS(Data!$C$2:$C$61,Data!$A$2:$A$61,$A33,Data!$B$2:$B$61,"101-500")+SUMIFS(Data!$C$2:$C$61,Data!$A$2:$A$61,$A33,Data!$B$2:$B$61,"501+"))/B33 -> 0.60985222
A34: 44562 | B34: =SUMIFS(Data!$C$2:$C$61,Data!$A$2:$A$61,$A34) -> 1915 | C34: =SUMIFS(Data!$D$2:$D$61,Data!$A$2:$A$61,$A34) -> 538 | D34: =SUMIFS(Data!$F$2:$F$61,Data!$A$2:$A$61,$A34) -> 120 | E34: =SUMIFS(Data!$G$2:$G$61,Data!$A$2:$A$61,$A34) -> 1284036 | F34: =C34/B34 -> 0.28093995 | G34: =D34/C34 -> 0.22304833 | H34: =E34/D34 -> 10700.3 | I34: =(SUMIFS(Data!$C$2:$C$61,Data!$A$2:$A$61,$A34,Data!$B$2:$B$61,"101-500")+SUMIFS(Data!$C$2:$C$61,Data!$A$2:$A$61,$A34,Data!$B$2:$B$61,"501+"))/B34 -> 0.61984334
A35: Total | B35: =SUM(B23:B34) -> 17152 | C35: =SUM(C23:C34) -> 4951 | D35: =SUM(D23:D34) -> 1082 | E35: =SUM(E23:E34) -> 10046367
A36: Nov-Dec 2021: leads fell ~47% vs Oct and every conversion rate dipped; Jan-22 set records. With one year of data, this is not confirmed seasonality.
A38: D. Early period (Feb-Jul-21) vs baseline (Aug-Oct-21): average month
A39: Metric | B39: Velocity (1-50) | C39: Emerging MM (51-100) | D39: Core MM (101-500) | E39: Enterprise (501+) | F39: Total | G39: Reading
A40: Segment | B40: Velocity (1-50) | C40: Emerging MM (51-100) | D40: Core MM (101-500) | E40: Enterprise (501+) | F40: Total
A41: Leads / month (early) | B41: =(SUMIFS(Data!$C$2:$C$61,Data!$I$2:$I$61,1,Data!$H$2:$H$61,B$40)/(COUNTIFS(Data!$I$2:$I$61,1)/5)) -> 319 | C41: =(SUMIFS(Data!$C$2:$C$61,Data!$I$2:$I$61,1,Data!$H$2:$H$61,C$40)/(COUNTIFS(Data!$I$2:$I$61,1)/5)) -> 261 | D41: =(SUMIFS(Data!$C$2:$C$61,Data!$I$2:$I$61,1,Data!$H$2:$H$61,D$40)/(COUNTIFS(Data!$I$2:$I$61,1)/5)) -> 542.83333 | E41: =(SUMIFS(Data!$C$2:$C$61,Data!$I$2:$I$61,1,Data!$H$2:$H$61,E$40)/(COUNTIFS(Data!$I$2:$I$61,1)/5)) -> 225 | F41: =(SUMIFS(Data!$C$2:$C$61,Data!$I$2:$I$61,1)/(COUNTIFS(Data!$I$2:$I$61,1)/5)) -> 1347.8333
A42: Leads / month (baseline) | B42: =(SUMIFS(Data!$C$2:$C$61,Data!$J$2:$J$61,1,Data!$H$2:$H$61,B$40)/(COUNTIFS(Data!$J$2:$J$61,1)/5)) -> 352.33333 | C42: =(SUMIFS(Data!$C$2:$C$61,Data!$J$2:$J$61,1,Data!$H$2:$H$61,C$40)/(COUNTIFS(Data!$J$2:$J$61,1)/5)) -> 308 | D42: =(SUMIFS(Data!$C$2:$C$61,Data!$J$2:$J$61,1,Data!$H$2:$H$61,D$40)/(COUNTIFS(Data!$J$2:$J$61,1)/5)) -> 707.66667 | E42: =(SUMIFS(Data!$C$2:$C$61,Data!$J$2:$J$61,1,Data!$H$2:$H$61,E$40)/(COUNTIFS(Data!$J$2:$J$61,1)/5)) -> 343.33333 | F42: =(SUMIFS(Data!$C$2:$C$61,Data!$J$2:$J$61,1)/(COUNTIFS(Data!$J$2:$J$61,1)/5)) -> 1711.3333
A43: Lead growth | B43: =B42/B41-1 -> 0.10449321 | C43: =C42/C41-1 -> 0.18007663 | D43: =D42/D41-1 -> 0.30365367 | E43: =E42/E41-1 -> 0.52592593 | F43: =F42/F41-1 -> 0.2696921 | G43: Demand grew in every segment except Velocity; Enterprise grew fastest.
A44: ARR / month (early) | B44: =(SUMIFS(Data!$G$2:$G$61,Data!$I$2:$I$61,1,Data!$H$2:$H$61,B$40)/(COUNTIFS(Data!$I$2:$I$61,1)/5)) -> 125561.33 | C44: =(SUMIFS(Data!$G$2:$G$61,Data!$I$2:$I$61,1,Data!$H$2:$H$61,C$40)/(COUNTIFS(Data!$I$2:$I$61,1)/5)) -> 253891.17 | D44: =(SUMIFS(Data!$G$2:$G$61,Data!$I$2:$I$61,1,Data!$H$2:$H$61,D$40)/(COUNTIFS(Data!$I$2:$I$61,1)/5)) -> 311471.33 | E44: =(SUMIFS(Data!$G$2:$G$61,Data!$I$2:$I$61,1,Data!$H$2:$H$61,E$40)/(COUNTIFS(Data!$I$2:$I$61,1)/5)) -> 122179.5 | F44: =(SUMIFS(Data!$G$2:$G$61,Data!$I$2:$I$61,1)/(COUNTIFS(Data!$I$2:$I$61,1)/5)) -> 813103.33
...

Sheet Staffing
A1: Staffing model: required capacity by segment
A2: Required capacity, NOT net-new hires (current headcount is not in the dataset). The allocation follows from the stated illustrative assumptions; it is not a claim of optimality.
B4: Line item | C4: Velocity (1-50) | D4: Emerging MM (51-100) | E4: Core MM (101-500) | F4: Enterprise (501+) | G4: Total | H4: Formula / note
B5: Segment | C5: Velocity (1-50) | D5: Emerging MM (51-100) | E5: Core MM (101-500) | F5: Enterprise (501+)
A6: 1. Baseline demand: average month, Aug-Oct 2021 (from Data)
B7: Leads / month | C7: =(SUMIFS(Data!$C$2:$C$61,Data!$H$2:$H$61,C$5,Data!$J$2:$J$61,1)/(COUNTIFS(Data!$J$2:$J$61,1)/5)) -> 352.33333 | D7: =(SUMIFS(Data!$C$2:$C$61,Data!$H$2:$H$61,D$5,Data!$J$2:$J$61,1)/(COUNTIFS(Data!$J$2:$J$61,1)/5)) -> 308 | E7: =(SUMIFS(Data!$C$2:$C$61,Data!$H$2:$H$61,E$5,Data!$J$2:$J$61,1)/(COUNTIFS(Data!$J$2:$J$61,1)/5)) -> 707.66667 | F7: =(SUMIFS(Data!$C$2:$C$61,Data!$H$2:$H$61,F$5,Data!$J$2:$J$61,1)/(COUNTIFS(Data!$J$2:$J$61,1)/5)) -> 343.33333 | G7: =SUM(C7:F7) -> 1711.3333 | H7: Average of the baseline months
B8: Demos / month | C8: =(SUMIFS(Data!$D$2:$D$61,Data!$H$2:$H$61,C$5,Data!$J$2:$J$61,1)/(COUNTIFS(Data!$J$2:$J$61,1)/5)) -> 127 | D8: =(SUMIFS(Data!$D$2:$D$61,Data!$H$2:$H$61,D$5,Data!$J$2:$J$61,1)/(COUNTIFS(Data!$J$2:$J$61,1)/5)) -> 108.66667 | E8: =(SUMIFS(Data!$D$2:$D$61,Data!$H$2:$H$61,E$5,Data!$J$2:$J$61,1)/(COUNTIFS(Data!$J$2:$J$61,1)/5)) -> 181.66667 | F8: =(SUMIFS(Data!$D$2:$D$61,Data!$H$2:$H$61,F$5,Data!$J$2:$J$61,1)/(COUNTIFS(Data!$J$2:$J$61,1)/5)) -> 65.333333 | G8: =SUM(C8:F8) -> 482.66667
B9: Lead->Demo | C9: =C8/C7 -> 0.36045412 | D9: =D8/D7 -> 0.35281385 | E9: =E8/E7 -> 0.2567122 | F9: =F8/F7 -> 0.19029126 | G9: =G8/G7 -> 0.28204129 | H9: Demos / leads
B10: Demo->Win (logos / demos) | C10: =((SUMIFS(Data!$F$2:$F$61,Data!$H$2:$H$61,C$5,Data!$J$2:$J$61,1)/(COUNTIFS(Data!$J$2:$J$61,1)/5)))/C8 -> 0.27034121 | D10: =((SUMIFS(Data!$F$2:$F$61,Data!$H$2:$H$61,D$5,Data!$J$2:$J$61,1)/(COUNTIFS(Data!$J$2:$J$61,1)/5)))/D8 -> 0.26993865 | E10: =((SUMIFS(Data!$F$2:$F$61,Data!$H$2:$H$61,E$5,Data!$J$2:$J$61,1)/(COUNTIFS(Data!$J$2:$J$61,1)/5)))/E8 -> 0.17981651 | F10: =((SUMIFS(Data!$F$2:$F$61,Data!$H$2:$H$61,F$5,Data!$J$2:$J$61,1)/(COUNTIFS(Data!$J$2:$J$61,1)/5)))/F8 -> 0.12755102 | G10: =SUMPRODUCT(C8:F8,C10:F10)/G8 -> 0.21685083 | H10: Logos / demos
B11: ARR / logo | C11: =((SUMIFS(Data!$G$2:$G$61,Data!$H$2:$H$61,C$5,Data!$J$2:$J$61,1)/(COUNTIFS(Data!$J$2:$J$61,1)/5)))/((SUMIFS(Data!$F$2:$F$61,Data!$H$2:$H$61,C$5,Data!$J$2:$J$61,1)/(COUNTIFS(Data!$J$2:$J$61,1)/5))) -> 3786.9806 | D11: =((SUMIFS(Data!$G$2:$G$61,Data!$H$2:$H$61,D$5,Data!$J$2:$J$61,1)/(COUNTIFS(Data!$J$2:$J$61,1)/5)))/((SUMIFS(Data!$F$2:$F$61,Data!$H$2:$H$61,D$5,Data!$J$2:$J$61,1)/(COUNTIFS(Data!$J$2:$J$61,1)/5))) -> 9498.9545 | E11: =((SUMIFS(Data!$G$2:$G$61,Data!$H$2:$H$61,E$5,Data!$J$2:$J$61,1)/(COUNTIFS(Data!$J$2:$J$61,1)/5)))/((SUMIFS(Data!$F$2:$F$61,Data!$H$2:$H$61,E$5,Data!$J$2:$J$61,1)/(COUNTIFS(Data!$J$2:$J$61,1)/5))) -> 12997.133 | F11: =((SUMIFS(Data!$G$2:$G$61,Data!$H$2:$H$61,F$5,Data!$J$2:$J$61,1)/(COUNTIFS(Data!$J$2:$J$61,1)/5)))/((SUMIFS(Data!$F$2:$F$61,Data!$H$2:$H$61,F$5,Data!$J$2:$J$61,1)/(COUNTIFS(Data!$J$2:$J$61,1)/5))) -> 23143.64 | G11: =SUMPRODUCT(C8:F8,C10:F10,C11:F11)/SUMPRODUCT(C8:F8,C10:F10) -> 9803.4299 | H11: ARR / logos
A13: 2. Staffing assumptions (linked from Inputs; illustrative)
B14: SDR lead capacity / month | C14: =Inputs!C$20 -> 300 | D14: =Inputs!D$20 -> 200 | E14: =Inputs!E$20 -> 175 | F14: =Inputs!F$20 -> 125
B15: AE demo capacity / month | C15: =Inputs!C$21 -> 45 | D15: =Inputs!D$21 -> 30 | E15: =Inputs!E$21 -> 20 | F15: =Inputs!F$21 -> 12
B16: SC engagement rate | C16: =Inputs!C$22 -> 0.05 | D16: =Inputs!D$22 -> 0.15 | E16: =Inputs!E$22 -> 0.5 | F16: =Inputs!F$22 -> 1
B17: SC engagement capacity / month | C17: =Inputs!C$23 -> 30 | D17: =Inputs!D$23 -> 30 | E17: =Inputs!E$23 -> 30 | F17: =Inputs!F$23 -> 20
B18: Target utilization | C18: =Inputs!C$24 -> 0.85 | D18: =Inputs!D$24 -> 0.85 | E18: =Inputs!E$24 -> 0.85 | F18: =Inputs!F$24 -> 0.85
A20: 3. Baseline required FTE (fractional workload)
B21: SDR FTE | C21: =C7/(C14*C18) -> 1.3816993 | D21: =D7/(D14*D18) -> 1.8117647 | E21: =E7/(E14*E18) -> 4.757423 | F21: =F7/(F14*F18) -> 3.2313725 | G21: =SUM(C21:F21) -> 11.18226 | H21: Leads / (SDR capacity x utilization)
B22: AE FTE | C22: =C8/(C15*C18) -> 3.3202614 | D22: =D8/(D15*D18) -> 4.2614379 | E22: =E8/(E15*E18) -> 10.686275 | F22: =F8/(F15*F18) -> 6.4052288 | G22: =SUM(C22:F22) -> 24.673203 | H22: Demos / (AE capacity x utilization)
B23: SC FTE | C23: =C8*C16/(C17*C18) -> 0.24901961 | D23: =D8*D16/(D17*D18) -> 0.63921569 | E23: =E8*E16/(E17*E18) -> 3.5620915 | F23: =F8*F16/(F17*F18) -> 3.8431373 | G23: =SUM(C23:F23) -> 8.2934641 | H23: Demos x SC rate / (SC capacity x utilization)
A25: 4. Recommended headcount, baseline (ROUNDUP; covers modeled workload)
B26: SDR (dedicated per segment) | C26: =ROUNDUP(C21,0) -> 2 | D26: =ROUNDUP(D21,0) -> 2 | E26: =ROUNDUP(E21,0) -> 5 | F26: =ROUNDUP(F21,0) -> 4 | G26: =SUM(C26:F26) -> 13 | H26: ROUNDUP of each segment's SDR FTE
B27: AE (dedicated per segment) | C27: =ROUNDUP(C22,0) -> 4 | D27: =ROUNDUP(D22,0) -> 5 | E27: =ROUNDUP(E22,0) -> 11 | F27: =ROUNDUP(F22,0) -> 7 | G27: =SUM(C27:F27) -> 27 | H27: ROUNDUP of each segment's AE FTE
B28: SC: shared pool (Velocity + Emerging MM + Core MM) | Enterprise | C28: =ROUNDUP(SUM(C23:E23),0) -> 5 | F28: =ROUNDUP(F23,0) -> 4 | G28: =C28+F28 -> 9 | H28: Pool = ROUNDUP of combined FTE in C23:E23. Enterprise = ROUNDUP of its own FTE.
B29: Total recommended headcount | G29: =G26+G27+G28 -> 49
B30: AEs per SDR | C30: =C27/C26 -> 2 | D30: =D27/D26 -> 2.5 | E30: =E27/E26 -> 2.2 | F30: =F27/F26 -> 1.75 | G30: =G27/G26 -> 2.0769231 | H30: Coverage ratio
B31: AEs per SC | C31: =SUM(C27:E27)/C28 -> 4 | F31: =F27/F28 -> 1.75 | G31: =G27/G28 -> 3 | H31: Shared pool: commercial AEs per pooled SC
B32: AE utilization at recommended headcount | C32: =C8/(C27*C15) -> 0.70555556 | D32: =D8/(D27*D15) -> 0.72444444 | E32: =E8/(E27*E15) -> 0.82575758 | F32: =F8/(F27*F15) -> 0.77777778 | G32: =G8/SUMPRODUCT(C27:F27,C15:F15) -> 0.76130389 | H32: Demos / (AE headcount x capacity). Below 85% = headroom created by rounding up.
A34: 5. Expected ARR, baseline (observed conversion; no improvement assumed)
B35: New ARR / month | C35: =C8*C10*C11 -> 130019.67 | D35: =D8*D10*D11 -> 278636 | E35: =E8*E10*E11 -> 424573 | F35: =F8*F10*F11 -> 192863.67 | G35: =SUM(C35:F35) -> 1026092.3 | H35: Demos x demo->win x ARR/logo (= observed baseline ARR)
B36: Annualized new ARR (x12) | C36: =C35*12 -> 1560236 | D36: =D35*12 -> 3343632 | E36: =E35*12 -> 5094876 | F36: =F35*12 -> 2314364 | G36: =SUM(C36:F36) -> 12313108 | H36: Run-rate. If the Nov-Dec dip recurs, annual ARR would be lower.
B37: ARR per AE (recommended headcount) | C37: =C36/C27 -> 390059 | D37: =D36/D27 -> 668726.4 | E37: =E36/E27 -> 463170.55 | F37: =F36/F27 -> 330623.43 | G37: =G36/G27 -> 456041.04 | H37: Productivity check only
A39: 6. Upside sensitivity: lead-to-demo recovers to the early-period level (NOT a forecast)
B40: Early-period Lead->Demo (Feb-Jul-21) | C40: =((SUMIFS(Data!$D$2:$D$61,Data!$H$2:$H$61,C$5,Data!$I$2:$I$61,1)/(COUNTIFS(Data!$I$2:$I$61,1)/5)))/((SUMIFS(Data!$C$2:$C$61,Data!$H$2:$H$61,C$5,Data!$I$2:$I$61,1)/(COUNTIFS(Data!$I$2:$I$61,1)/5))) -> 0.39550679 | D40: =((SUMIFS(Data!$D$2:$D$61,Data!$H$2:$H$61,D$5,Data!$I$2:$I$61,1)/(COUNTIFS(Data!$I$2:$I$61,1)/5)))/((SUMIFS(Data!$C$2:$C$61,Data!$H$2:$H$61,D$5,Data!$I$2:$I$61,1)/(COUNTIFS(Data!$I$2:$I$61,1)/5))) -> 0.38952746 | E40: =((SUMIFS(Data!$D$2:$D$61,Data!$H$2:$H$61,E$5,Data!$I$2:$I$61,1)/(COUNTIFS(Data!$I$2:$I$61,1)/5)))/((SUMIFS(Data!$C$2:$C$61,Data!$H$2:$H$61,E$5,Data!$I$2:$I$61,1)/(COUNTIFS(Data!$I$2:$I$61,1)/5))) -> 0.27479275 | F40: =((SUMIFS(Data!$D$2:$D$61,Data!$H$2:$H$61,F$5,Data!$I$2:$I$61,1)/(COUNTIFS(Data!$I$2:$I$61,1)/5)))/((SUMIFS(Data!$C$2:$C$61,Data!$H$2:$H$61,F$5,Data!$I$2:$I$61,1)/(COUNTIFS(Data!$I$2:$I$61,1)/5))) -> 0.19407407
B41: Recovery applied? (from Inputs) | C41: =Inputs!C$27 -> 1 | D41: =Inputs!D$27 -> 1 | E41: =Inputs!E$27 -> 1 | F41: =Inputs!F$27 -> 0
B42: Upside Lead->Demo | C42: =IF(C41=1,MAX(C9,C40),C9) -> 0.39550679 | D42: =IF(D41=1,MAX(D9,D40),D9) -> 0.38952746 | E42: =IF(E41=1,MAX(E9,E40),E9) -> 0.27479275 | F42: =IF(F41=1,MAX(F9,F40),F9) -> 0.19029126 | G42: =G43/G7 -> 0.30334224
B43: Upside demos / month | C43: =C7*C42 -> 139.35023 | D43: =D7*D42 -> 119.97446 | E43: =E7*E42 -> 194.46167 | F43: =F7*F42 -> 65.333333 | G43: =SUM(C43:F43) -> 519.11969 | H43: Same leads as baseline; a higher share reaches a demo
B44: Upside AE FTE | C44: =C43/(C15*C18) -> 3.6431432 | D44: =D43/(D15*D18) -> 4.7048807 | E44: =E43/(E15*E18) -> 11.438922 | F44: =F43/(F15*F18) -> 6.4052288 | G44: =SUM(C44:F44) -> 26.192175
B45: Upside SC FTE | C45: =C43*C16/(C17*C18) -> 0.27323574 | D45: =D43*D16/(D17*D18) -> 0.7057321 | E45: =E43*E16/(E17*E18) -> 3.812974 | F45: =F43*F16/(F17*F18) -> 3.8431373 | G45: =SUM(C45:F45) -> 8.6350791
B46: Upside SDR headcount | C46: =C26 -> 2 | D46: =D26 -> 2 | E46: =E26 -> 5 | F46: =F26 -> 4 | G46: =SUM(C46:F46) -> 13 | H46: Unchanged: SDRs are sized to leads, which do not change
...

Sheet Cost_Optional
A1: OPTIONAL appendix: illustrative staffing cost of recommended headcount
A2: Illustrative SF fully loaded annual cost (salary + variable at target + benefits/taxes). Validate with Comp. Not an ROI, CAC or payback analysis.
B4: Role | C4: Loaded cost / FTE (illustrative) | D4: Baseline headcount | E4: Baseline cost | F4: Upside headcount | G4: Upside cost
B5: SDR | C5: 115000 | D5: =Staffing!G26 -> 13 | E5: =C5*D5 -> 1495000 | F5: =Staffing!G46 -> 13 | G5: =C5*F5 -> 1495000
B6: AE (blended across segments) | C6: 250000 | D6: =Staffing!G27 -> 27 | E6: =C6*D6 -> 6750000 | F6: =Staffing!G47 -> 28 | G6: =C6*F6 -> 7000000
B7: SC | C7: 265000 | D7: =Staffing!G28 -> 9 | E7: =C7*D7 -> 2385000 | F7: =Staffing!G48 -> 9 | G7: =C7*F7 -> 2385000
B8: Total | D8: =SUM(D5:D7) -> 49 | E8: =SUM(E5:E7) -> 10630000 | F8: =SUM(F5:F7) -> 50 | G8: =SUM(G5:G7) -> 10880000
B10: Use: a sense of scale for the required capacity. Current headcount is unknown, so this is NOT incremental spend.
B11: AE pay varies by segment in practice (Enterprise higher, Velocity lower). One blended figure keeps this optional view simple.

Sheet Checks
A1: Reconciliation checks
A2: Every row should read TRUE.
B4: Check | C4: Value A | D4: Value B | E4: Pass?
B5: Data has 60 rows (12 months x 5 buckets) | C5: =COUNTA(Data!$B$2:$B$61) -> 60 | D5: =60 -> 60 | E5: =ABS(C5-D5)<0.01 -> TRUE
B6: Funnel segment total leads = sum of Data leads | C6: =Funnel!B10 -> 17152 | D6: =SUM(Data!$C$2:$C$61) -> 17152 | E6: =ABS(C6-D6)<0.01 -> TRUE
B7: Funnel segment total ARR = sum of Data ARR | C7: =Funnel!F10 -> 10046367 | D7: =SUM(Data!$G$2:$G$61) -> 10046367 | E7: =ABS(C7-D7)<0.01 -> TRUE
B8: Funnel bucket total ARR = segment total ARR | C8: =Funnel!F19 -> 10046367 | D8: =Funnel!F10 -> 10046367 | E8: =ABS(C8-D8)<0.01 -> TRUE
B9: Monthly trend ARR = segment total ARR | C9: =Funnel!E35 -> 10046367 | D9: =Funnel!F10 -> 10046367 | E9: =ABS(C9-D9)<0.01 -> TRUE
B10: Staffing baseline leads/month = Data baseline leads / months | C10: =Staffing!G7 -> 1711.3333 | D10: =SUMIFS(Data!$C$2:$C$61,Data!$J$2:$J$61,1)/(COUNTIFS(Data!$J$2:$J$61,1)/5) -> 1711.3333 | E10: =ABS(C10-D10)<0.01 -> TRUE
B11: Staffing baseline ARR/month = Data baseline ARR / months | C11: =Staffing!G35 -> 1026092.3 | D11: =SUMIFS(Data!$G$2:$G$61,Data!$J$2:$J$61,1)/(COUNTIFS(Data!$J$2:$J$61,1)/5) -> 1026092.3 | E11: =ABS(C11-D11)<0.01 -> TRUE
B12: Staffing baseline leads = Funnel baseline leads | C12: =Staffing!G7 -> 1711.3333 | D12: =Funnel!F42 -> 1711.3333 | E12: =ABS(C12-D12)<0.01 -> TRUE
B13: SDR headcount covers SDR FTE (every segment) | C13: =SUMPRODUCT((Staffing!C26:F26<Staffing!C21:F21)*1) -> 0 | D13: =0 -> 0 | E13: =ABS(C13-D13)<0.01 -> TRUE
B14: AE headcount covers AE FTE (every segment) | C14: =SUMPRODUCT((Staffing!C27:F27<Staffing!C22:F22)*1) -> 0 | D14: =0 -> 0 | E14: =ABS(C14-D14)<0.01 -> TRUE
B15: SC pool covers pooled SC FTE | C15: =Staffing!C28 -> 5 | D15: =SUM(Staffing!C23:E23) -> 4.4503268 | E15: =C15>=D15-0.0001 -> TRUE
B16: Enterprise SC covers Enterprise SC FTE | C16: =Staffing!F28 -> 4 | D16: =Staffing!F23 -> 3.8431373 | E16: =C16>=D16-0.0001 -> TRUE
B17: Total headcount = SDR + AE + SC | C17: =Staffing!G29 -> 49 | D17: =SUM(Staffing!G26:G28) -> 49 | E17: =ABS(C17-D17)<0.01 -> TRUE
B18: Upside headcount >= baseline headcount | C18: =Staffing!G49 -> 50 | D18: =Staffing!G29 -> 49 | E18: =C18>=D18-0.0001 -> TRUE
B19: Upside ARR >= baseline ARR | C19: =Staffing!G50 -> 13171609 | D19: =Staffing!G36 -> 12313108 | E19: =C19>=D19-0.0001 -> TRUE
B20: Cost tab headcount = Staffing headcount | C20: =Cost_Optional!D8 -> 49 | D20: =Staffing!G29 -> 49 | E20: =ABS(C20-D20)<0.01 -> TRUE
B22: ALL CHECKS PASS | E22: =AND(E5:E20) -> TRUE
